Workbook
Name _Toc135440555: 'Ante Proyecto Estructural'!#REF!
Name _Toc135440555: formulas!$AAB$4
Name type1: #REF!
Name type10: #REF!
Name type11: #REF!
Name type12: #REF!
Name type13: #REF!
Name type2: #REF!
Name type3: #REF!
Name type4: #REF!
Name type5: #REF!
Name type6: #REF!
Name type7: #REF!
Name type8: #REF!
Name type9: #REF!

Sheet Ante Proyecto Estructural
B4: Memoria Estructural | L4: Antecedentes Geológicos. | U4: Análisis Histórico | AD4: Analisis Por Viento: | BY4: VALOR DEL EXPONENTE X. | DD4: Opcion Seleccionada para Estructura | DM4: Analisis Dinamico de Estructura | EF4: claro maximo por momento | EN4: Bajando Cargas: | EW4: Análisis por elemento Finito | FF4: Análisis de Trabe Tipo como Continua Con Voladizo | GD4: Análisis de Trabe Tipo como Continua Arriostrada Parcialmente | GZ4: Analisis de Trabe Tipo como Continua Totalmente Arriostrada | IY4: Condiciones | KC4: Losas de Entrepiso Opción 1 Vigueta y Bovedilla
B5: Ampliacion de Recamara Principal de Villa en Palacio del mar | AD5: Debido a la incidencia de vientos de velocidad considerable asi como la pretendida utilización de materiales livianos debemos tener especial cuidado con el análisis de viento. | BY5: TOPOGRAFIA | CD5: VELOCIDAD DEL VIENTO MENOR DE 100 km/h | CH5: FL = N CL Vz^2 A | CP5: P rafa = | CQ5: =BZ29 -> 0.0048 | CR5: x | CS5: =CB29 -> 1 | CT5: x | CU5: =CD29 -> 127.29062 | CV5: ^2 = | CW5: =CQ5*CS5*(CU5^2) -> 77.773935 | DD5: Esquemático | EG5: Wb = 120 Fb KS / l1^2 | EN5: Área de Construccion | ES5: 36 | IJ5: 1 metro | IM5: Tension | IO5: Fy | IR5: Conecciones Concreto Acero | IY5: Analisis Eolico | KC5: =#REF! -> #REF!
B6: Dirección: | L6: Se verificaron datos geológicos de la zona. | U6: Se revisaron fotografías históricas para buscar indicios de movimientos o deslizamientos antiguos. Al menos en la historia fotográfica. | BY6: Terreno plano | CE6: 0.15 | CH6: FT = N CT Vz^2 A | CQ6: =CQ5 -> 0.0048 | CR6: =CR5 -> x | CS6: =CS5 -> 1 | CT6: =CT5 -> x | CU6: =CU5*0.8 -> 101.8325 | CV6: =CV5 -> ^2 = | CW6: =CQ6*CS6*(CU6^2) -> 49.775319 | DX6: Wux | EG6: Wb= Carga uniformemente repartida permisible | EN6: Capacidad de carca: | FF6: W= | FG6: =ES18+150 -> 585.4 | GD6: W= | GE6: =FG6 -> 585.4 | GZ6: W= | HA6: =GE6 -> 585.4 | IO6: 36000 | IP6: lbs-plg^2 | IY6: =CQ41 -> Se puede apreciar una convergencia de periodos de oscilacion en la direccion de viento en vortices de entre 3 a 4 segundos para velocidades que van de 5 a 132 km/hra. Esto equivale aproximadamente a elementos en voladizo (pendulos) de 2.2 a 4 metros por cuanto se debe tener cuidado de arriostrar los elementos adecuadamente a no mas de 1,5 metros entre arriostramiento. Los elementos que funcionen como verticales en la canceleria podrian ser una buena opcion para arriostrar los elementos en voladizo. En teoria se pudiera suponer que los canceles en si realizan estta funcion pero seria entonces vidrio quien resistiria la vibracion de la estructura lo cual no es recomendable.
B7: Km 50 Carretera Rosarito - Ensenada | BY7: Zonas accidentadas | CE7: 0.1 | CH7: A: Area Expuesta | CQ7: =CQ6 -> 0.0048 | CR7: =CR6 -> x | CS7: =CS6 -> 1 | CT7: =CT6 -> x | CU7: =CU5*0.6 -> 76.374375 | CV7: =CV6 -> ^2 = | CW7: =CQ7*CS7*(CU7^2) -> 27.998617 | DJ7: Trabes Principales | EG7: Fb = esfuerzo maximo permisible psi | EN7: Techumbre liviana | ES7: =DX15 -> 112 | ET7: =ES7 -> 112 | FF7: Ancho= | FG7: 3 | FJ7: momento puro en el claro | FL7: Atrib | FM7: 3 | FP7: momento puro en el claro | GD7: Ancho= | GE7: 3 | GH7: momento puro en el claro | GJ7: Atrib | GK7: 3 | GN7: momento puro en el claro | GZ7: =GD7 -> Ancho= | HA7: =GE7 -> 3 | HD7: momento puro en el claro | HF7: Atrib | HG7: 3 | HJ7: momento puro en el claro | HP7: momento puro en el claro | HV7: momento puro en el claro | IO7: =IO6/(2.2*2.54*2.54) -> 2536.3687 | IP7: kgs-cm^2 | IR7: Reaccion Maxima | IT7: F'c | IU7: Area Req | IV7: 20 x 20
AD8: Paralelamente se pretenden colocar amplios canceles por cuanto debemos conocer los esfuerzos a los que estos estaran sujetos a efecto de los vientos. | BY8: Centros de ciudades Zonas arboladas | CE8: 0.35 | CH8: VL y VT por tabla | CQ8: =CQ7 -> 0.0048 | CR8: =CR7 -> x | CS8: =CS7 -> 1 | CT8: =CT7 -> x | CU8: =CU5*0.4 -> 50.91625 | CV8: =CV7 -> ^2 = | CW8: =CQ8*CS8*(CU8^2) -> 12.44383 | EG8: KS = modulo de seccion en plg^3 | EN8: Techumbre | FF8: W16x40 | FG8: =40*3.28/2.2 -> 59.636364 | FK8: momentos generados en los nudos | FL8: A | FM8: B | FQ8: momentos generados en los nudos | FR8: A | FS8: B | GD8: W16x40 | GE8: =40*3.28/2.2 -> 59.636364 | GI8: momentos generados en los nudos | GJ8: A | GK8: B | GO8: momentos generados en los nudos | GP8: A | GQ8: B | GZ8: =GD8 -> W16x40 | HA8: =GE8 -> 59.636364 | HE8: momentos generados en los nudos | HF8: A | HG8: B | HK8: momentos generados en los nudos | HL8: A | HM8: B | HQ8: momentos generados en los nudos | HR8: A | HS8: B | HW8: momentos generados en los nudos | HX8: A | HY8: B | IR8: =FI28 -> 11367.361 | IT8: 200 | IU8: =IR8/IT8 -> 56.836807 | IV8: =20*20 -> 400 | IW8: pasa | KC8: =OV5 -> 0
CH9: Consideramos un Valor de 2 tanto para CL como para CT | CQ9: =CQ8 -> 0.0048 | CR9: =CR8 -> x | CS9: =CS8 -> 1 | CT9: =CT8 -> x | CU9: =CU5*0.2 -> 25.458125 | CV9: =CV8 -> ^2 = | CW9: =CQ9*CS9*(CU9^2) -> 3.1109574 | DJ9: Trabe Secundaria | EG9: l1 = claro entre apoyos | EN9: carga viva | ES9: 150 | ET9: kg | FF9: P.conc | FG9: =140+(31*3.28*3/2.2) -> 278.65455 | FJ9: Carga uniformemente Distribuida | FK9: =FG6*FG7 -> 1756.2 | FL9: =-1*(IF(FL24=0,0,IF(FK9=0,0,FK9*FL24*FL24/12))) -> -1317.15 | FM9: =FL9*-1 -> 1317.15 | FP9: Carga uniformemente Distribuida | FR9: =-1*(IF(FR24=0,0,IF(FQ9=0,0,FQ9*FR24*FR24/12))) -> 0 | FS9: =FR9*-1 -> 0 | GD9: =FF9 -> P.conc | GE9: =FG9 -> 278.65455 | GH9: Carga uniformemente Distribuida | GI9: =GE6*GE7 -> 1756.2 | GJ9: =-1*(IF(GJ24=0,0,IF(GI9=0,0,GI9*GJ24*GJ24/12))) -> -1317.15 | GK9: =GJ9*-1 -> 1317.15 | GN9: Carga uniformemente Distribuida | GO9: =GI9 -> 1756.2 | GP9: =-1*(IF(GP24=0,0,IF(GO9=0,0,GO9*GP24*GP24/12))) -> -1317.15 | GQ9: =GP9*-1 -> 1317.15 | GZ9: =GD9 -> P.conc | HA9: =GE9 -> 278.65455 | HD9: Carga uniformemente Distribuida | HE9: =HA6*HA7 -> 1756.2 | HF9: =-1*(IF(HF24=0,0,IF(HE9=0,0,HE9*HF24*HF24/12))) -> -146.35 | HG9: =HF9*-1 -> 146.35 | HJ9: Carga uniformemente Distribuida | HK9: =HE9 -> 1756.2 | HL9: =-1*(IF(HL24=0,0,IF(HK9=0,0,HK9*HL24*HL24/12))) -> -146.35 | HM9: =HL9*-1 -> 146.35 | HP9: Carga uniformemente Distribuida | HQ9: =HK9 -> 1756.2 | HR9: =-1*(IF(HR24=0,0,IF(HQ9=0,0,HQ9*HR24*HR24/12))) -> -146.35 | HS9: =HR9*-1 -> 146.35 | HV9: Carga uniformemente Distribuida | HW9: =HQ9 -> 1756.2 | HX9: =-1*(IF(HX24=0,0,IF(HW9=0,0,HW9*HX24*HX24/12))) -> -1317.15 | HY9: =HX9*-1 -> 1317.15
BY10: Vz = Vß X Z | CS10: presion | EG10: para triplay de 1" estructural | EN10: carga muerta | EP10: losa + acabados | ES10: =ET7+50 -> 162 | ET10: kg | FF10: Mmax= | FG10: =FH42 -> 8111.8909 | FJ10: Carga uniforme por peso prop | FK10: =FG8 -> 59.636364 | FL10: =-1*(IF(FL24=0,0,IF(FK10=0,0,FK10*FL24*FL24/12))) -> -44.727273 | FM10: =FL10*-1 -> 44.727273 | FP10: Carga uniforme por peso prop | FR10: =-1*(IF(FR24=0,0,IF(FQ10=0,0,FQ10*FR24*FR24/12))) -> 0 | FS10: =FR10*-1 -> 0 | GD10: Mmax= | GE10: =GF42 -> 1480.1955 | GH10: Carga uniforme por peso prop | GI10: =GE8 -> 59.636364 | GJ10: =-1*(IF(GJ24=0,0,IF(GI10=0,0,GI10*GJ24*GJ24/12))) -> -44.727273 | GK10: =GJ10*-1 -> 44.727273 | GN10: Carga uniforme por peso prop | GO10: =GI10 -> 59.636364 | GP10: =-1*(IF(GP24=0,0,IF(GO10=0,0,GO10*GP24*GP24/12))) -> -44.727273 | GQ10: =GP10*-1 -> 44.727273 | GZ10: Mmax= | HA10: =HB42 -> 1529.2334 | HD10: Carga uniforme por peso prop | HE10: =HA8 -> 59.636364 | HF10: =-1*(IF(HF24=0,0,IF(HE10=0,0,HE10*HF24*HF24/12))) -> -4.969697 | HG10: =HF10*-1 -> 4.969697 | HJ10: Carga uniforme por peso prop | HK10: =HE10 -> 59.636364 | HL10: =-1*(IF(HL24=0,0,IF(HK10=0,0,HK10*HL24*HL24/12))) -> -4.969697 | HM10: =HL10*-1 -> 4.969697 | HP10: Carga uniforme por peso prop | HQ10: =HK10 -> 59.636364 | HR10: =-1*(IF(HR24=0,0,IF(HQ10=0,0,HQ10*HR24*HR24/12))) -> -4.969697 | HS10: =HR10*-1 -> 4.969697 | HV10: Carga uniforme por peso prop | HW10: =HQ10 -> 59.636364 | HX10: =-1*(IF(HX24=0,0,IF(HW10=0,0,HW10*HX24*HX24/12))) -> -44.727273 | HY10: =HX10*-1 -> 44.727273 | IK10: Distancia | IR10: Debido a la configuracion de la estructura de soporte disenada como puente colgante se pretende que el unico esfuerzo que transmita a los apoyos sea cortante directo. Por lo tanto bastara con que se anclaran a columnas - castillo de 30 x 30 constuidas dentro del muro en los puntos de apoyo. Estos estaran armados con 4 varillas de 5/8" y varillas de 1/2" en los centros. estribos de 3/8" @ 15 cm. en anclaje se hara con las varillas sin doblar soldadas por lo menos en 4 ". El apoyo suplementario en la punta de viga palanca funcionara a tension, por cuanto se debera extremar cuidado en la coneccion. | KC10: Losas de Entrepiso Opción 2 Maciza
AD11: Análisis Estático | BY11: Vz = | BZ11: =BR42 -> 15.2352 | CA11: x | CB11: 2.5 | CC11: x | CD11: 0.35 | CE11: = | CF11: =BZ11*CB11*CD11 -> 13.3308 | CQ11: FL prom = | CR11: 0.0048 | CS11: 2 | CT11: =CU5 -> 127.29062 | CV11: =CF46 -> 6 | CW11: =CR11*CS11*(CT11^2)*CV11 -> 933.28723 | DJ11: Castillo Metálico | EG11: Fb = | EH11: 1110 | EI11: lbs/plg^3 | EN11: viento | ES11: =CF29 -> 77.773935 | ET11: kg | FF11: en kg/cm | FG11: =FG10*100 -> 811189.09 | FJ11: Distancia de nudo a carga puntual | FL11: =-1*(IF(FL24=0,0,IF(FK11=0,0,IF(FK12=0,0,IF(FK11=(FL24/2),FK12*FL24/8,FK12*FK11*((FL24-FK11)*(FL24-FK11))/(FL24*FL24)))))) -> 0 | FM11: =IF(FL24=0,0,IF(FK11=0,0,IF(FK12=0,0,IF(FK11=(FL24/2),FL11*-1,FK12*(FK11*FK11)*(FL24-FK11)/(FL24*FL24))))) -> 0 | FP11: Distancia de nudo a carga puntual | FR11: =-1*(IF(FR24=0,0,IF(FQ11=0,0,IF(FQ12=0,0,IF(FQ11=(FR24/2),FQ12*FR24/8,FQ12*FQ11*((FR24-FQ11)*(FR24-FQ11))/(FR24*FR24)))))) -> 0 | FS11: =IF(FR24=0,0,IF(FQ11=0,0,IF(FQ12=0,0,IF(FQ11=(FR24/2),FR11*-1,FQ12*(FQ11*FQ11)*(FR24-FQ11)/(FR24*FR24))))) -> 0 | GD11: en kg/cm | GE11: =GE10*100 -> 148019.55 | GH11: Distancia de nudo a carga puntual | GJ11: =-1*(IF(GJ24=0,0,IF(GI11=0,0,IF(GI12=0,0,IF(GI11=(GJ24/2),GI12*GJ24/8,GI12*GI11*((GJ24-GI11)*(GJ24-GI11))/(GJ24*GJ24)))))) -> 0 | GK11: =IF(GJ24=0,0,IF(GI11=0,0,IF(GI12=0,0,IF(GI11=(GJ24/2),GJ11*-1,GI12*(GI11*GI11)*(GJ24-GI11)/(GJ24*GJ24))))) -> 0 | GN11: Distancia de nudo a carga puntual | GP11: =-1*(IF(GP24=0,0,IF(GO11=0,0,IF(GO12=0,0,IF(GO11=(GP24/2),GO12*GP24/8,GO12*GO11*((GP24-GO11)*(GP24-GO11))/(GP24*GP24)))))) -> 0 | GQ11: =IF(GP24=0,0,IF(GO11=0,0,IF(GO12=0,0,IF(GO11=(GP24/2),GP11*-1,GO12*(GO11*GO11)*(GP24-GO11)/(GP24*GP24))))) -> 0 | GZ11: en kg/cm | HA11: =HA10*100 -> 152923.34 | HD11: Distancia de nudo a carga puntual | HE11: 0.1 | HF11: =-1*(IF(HF24=0,0,IF(HE11=0,0,IF(HE12=0,0,IF(HE11=(HF24/2),HE12*HF24/8,HE12*HE11*((HF24-HE11)*(HF24-HE11))/(HF24*HF24)))))) -> -22.571018 | HG11: =IF(HF24=0,0,IF(HE11=0,0,IF(HE12=0,0,IF(HE11=(HF24/2),HF11*-1,HE12*(HE11*HE11)*(HF24-HE11)/(HF24*HF24))))) -> 2.5078909 | HJ11: Distancia de nudo a carga puntual | HL11: =-1*(IF(HL24=0,0,IF(HK11=0,0,IF(HK12=0,0,IF(HK11=(HL24/2),HK12*HL24/8,HK12*HK11*((HL24-HK11)*(HL24-HK11))/(HL24*HL24)))))) -> 0 | HM11: =IF(HL24=0,0,IF(HK11=0,0,IF(HK12=0,0,IF(HK11=(HL24/2),HL11*-1,HK12*(HK11*HK11)*(HL24-HK11)/(HL24*HL24))))) -> 0 | HP11: Distancia de nudo a carga puntual | HQ11: =GB11 -> 0 | HR11: =-1*(IF(HR24=0,0,IF(HQ11=0,0,IF(HQ12=0,0,IF(HQ11=(HR24/2),HQ12*HR24/8,HQ12*HQ11*((HR24-HQ11)*(HR24-HQ11))/(HR24*HR24)))))) -> 0 | HS11: =IF(HR24=0,0,IF(HQ11=0,0,IF(HQ12=0,0,IF(HQ11=(HR24/2),HR11*-1,HQ12*(HQ11*HQ11)*(HR24-HQ11)/(HR24*HR24))))) -> 0 | HV11: Distancia de nudo a carga puntual | HX11: =-1*(IF(HX24=0,0,IF(HW11=0,0,IF(HW12=0,0,IF(HW11=(HX24/2),HW12*HX24/8,HW12*HW11*((HX24-HW11)*(HX24-HW11))/(HX24*HX24)))))) -> 0 | HY11: =IF(HX24=0,0,IF(HW11=0,0,IF(HW12=0,0,IF(HW11=(HX24/2),HX11*-1,HW12*(HW11*HW11)*(HX24-HW11)/(HX24*HX24))))) -> 0 | JH11: Muros Estructurales ME | KC11: =PQ31 -> 0
CR12: 0.0048 | CS12: 2 | CT12: =CU6 -> 101.8325 | CV12: 6 | CW12: =CR12*CS12*(CT12^2)*CV12 -> 597.30382 | DW12: Carga viva = | DX12: 150 | DY12: kg/m^2 | DZ12: =IF(DY12="kg/m^2",1,IF(DY12="lbs/pis^2",2,3)) -> 1 | EG12: KS = | EH12: 0.412 | EI12: plg^3 | EN12: lluvia | EP12: I cm | ES12: 2 | ET12: kg | FF12: Fy | FG12: 2500 | FJ12: Carga Puntual | FP12: Carga Puntual | GD12: Fy | GE12: 2500 | GH12: Carga Puntual | GN12: Carga Puntual | GZ12: Fy | HA12: 2500 | HD12: Carga Puntual | HE12: =HA9 -> 278.65455 | HJ12: Carga Puntual | HP12: Carga Puntual | HQ12: =GB12 -> 0 | HV12: Carga Puntual | IK12: Tensores | JH12: Armado con celdas coladas @3er celda Varilla vertical #4 , varilla longitudinal @ 2 hiladas amarrada a las varillas verticales. Block 1 Estos se colocaran en todos los laterales de la planta baja y alta a excepción de los muros en ángulo en cocina y recamara. Así como los muros indicados en las observaciones. | KC12: Losas de Cimentación
AD13: Primero se tiene que analizar la respuesta a Presiones Estaticas como con cualquier otra estructura, sin embargo, debido a los techos bolados deberemos poner especial atencion a los efectos de "Rafaga", de "Arrastre" y "Vortice". | BY13: Vz = | BZ13: =BR44 -> 145.475 | CA13: x | CB13: 2.5 | CC13: x | CD13: 0.35 | CE13: = | CF13: =BZ13*CB13*CD13 -> 127.29062 | CR13: 0.0048 | CS13: 2 | CT13: =CU7 -> 76.374375 | CV13: 6 | CW13: =CR13*CS13*(CT13^2)*CV13 -> 335.9834 | DJ13: Placa o Caja de Conección | DW13: Carga muerta = | DX13: 100 | DY13: kg/m^2 | DZ13: =IF(DY13="kg/m^2",1,IF(DY13="lbs/pis^2",2,3)) -> 1 | EG13: P.P. = | EH13: 2.2 | EI13: lbs/pie^2 | EN13: combinaciones de carga | FF13: Sreq | FG13: =FG11/FG12 -> 324.47564 | FJ13: Distancia de nudo a carga puntual | FL13: =-1*(IF(FL24=0,0,IF(FK13=0,0,IF(FK14=0,0,IF(FK13=(FL24/2),FK14*FL24/8,FK14*FK13*((FL24-FK13)*(FL24-FK13))/(FL24*FL24)))))) -> 0 | FM13: =IF(FL24=0,0,IF(FK13=0,0,IF(FK14=0,0,IF(FK13=(FL24/2),FL13*-1,FK14*(FK13*FK13)*(FL24-FK13)/(FL24*FL24))))) -> 0 | FP13: Distancia de nudo a carga puntual | FR13: =-1*(IF(FR24=0,0,IF(FQ13=0,0,IF(FQ14=0,0,IF(FQ13=(FR24/2),FQ14*FR24/8,FQ14*FQ13*((FR24-FQ13)*(FR24-FQ13))/(FR24*FR24)))))) -> 0 | FS13: =IF(FR24=0,0,IF(FQ13=0,0,IF(FQ14=0,0,IF(FQ13=(FR24/2),FR13*-1,FQ14*(FQ13*FQ13)*(FR24-FQ13)/(FR24*FR24))))) -> 0 | GD13: Sreq | GE13: =GE11/GE12 -> 59.207818 | GH13: Distancia de nudo a carga puntual | GJ13: =-1*(IF(GJ24=0,0,IF(GI13=0,0,IF(GI14=0,0,IF(GI13=(GJ24/2),GI14*GJ24/8,GI14*GI13*((GJ24-GI13)*(GJ24-GI13))/(GJ24*GJ24)))))) -> 0 | GK13: =IF(GJ24=0,0,IF(GI13=0,0,IF(GI14=0,0,IF(GI13=(GJ24/2),GJ13*-1,GI14*(GI13*GI13)*(GJ24-GI13)/(GJ24*GJ24))))) -> 0 | GN13: Distancia de nudo a carga puntual | GP13: =-1*(IF(GP24=0,0,IF(GO13=0,0,IF(GO14=0,0,IF(GO13=(GP24/2),GO14*GP24/8,GO14*GO13*((GP24-GO13)*(GP24-GO13))/(GP24*GP24)))))) -> 0 | GQ13: =IF(GP24=0,0,IF(GO13=0,0,IF(GO14=0,0,IF(GO13=(GP24/2),GP13*-1,GO14*(GO13*GO13)*(GP24-GO13)/(GP24*GP24))))) -> 0 | GZ13: Z req | HA13: =HA11/HA12 -> 61.169335 | HD13: Distancia de nudo a carga puntual | HF13: =-1*(IF(HF24=0,0,IF(HE13=0,0,IF(HE14=0,0,IF(HE13=(HF24/2),HE14*HF24/8,HE14*HE13*((HF24-HE13)*(HF24-HE13))/(HF24*HF24)))))) -> 0 | HG13: =IF(HF24=0,0,IF(HE13=0,0,IF(HE14=0,0,IF(HE13=(HF24/2),HF13*-1,HE14*(HE13*HE13)*(HF24-HE13)/(HF24*HF24))))) -> 0 | HJ13: Distancia de nudo a carga puntual | HL13: =-1*(IF(HL24=0,0,IF(HK13=0,0,IF(HK14=0,0,IF(HK13=(HL24/2),HK14*HL24/8,HK14*HK13*((HL24-HK13)*(HL24-HK13))/(HL24*HL24)))))) -> 0 | HM13: =IF(HL24=0,0,IF(HK13=0,0,IF(HK14=0,0,IF(HK13=(HL24/2),HL13*-1,HK14*(HK13*HK13)*(HL24-HK13)/(HL24*HL24))))) -> 0 | HP13: Distancia de nudo a carga puntual | HR13: =-1*(IF(HR24=0,0,IF(HQ13=0,0,IF(HQ14=0,0,IF(HQ13=(HR24/2),HQ14*HR24/8,HQ14*HQ13*((HR24-HQ13)*(HR24-HQ13))/(HR24*HR24)))))) -> 0 | HS13: =IF(HR24=0,0,IF(HQ13=0,0,IF(HQ14=0,0,IF(HQ13=(HR24/2),HR13*-1,HQ14*(HQ13*HQ13)*(HR24-HQ13)/(HR24*HR24))))) -> 0 | HV13: Distancia de nudo a carga puntual | HX13: =-1*(IF(HX24=0,0,IF(HW13=0,0,IF(HW14=0,0,IF(HW13=(HX24/2),HW14*HX24/8,HW14*HW13*((HX24-HW13)*(HX24-HW13))/(HX24*HX24)))))) -> 0 | HY13: =IF(HX24=0,0,IF(HW13=0,0,IF(HW14=0,0,IF(HW13=(HX24/2),HX13*-1,HW14*(HW13*HW13)*(HX24-HW13)/(HX24*HX24))))) -> 0 | IJ13: Reacciones | IK13: Distancia | IL13: Hipotenusa | IM13: Tension | IN13: Area Req | IO13: Tension H | KC13: Espesor 15 cm. Armado a base de varillas #4 @ 13 en ambas direcciones en el lecho superior, en los ejes de marco se aumentara el espesor a 20 cm armando un metro con varilla #4 @ 13 en el lecho inferior como zapata invertida. Finalmente se colocara una trabe de liga de 35 x 50 para absorber posibles asentamientos Armada comola Trabe T2.
CR14: 0.0048 | CS14: 2 | CT14: =CU8 -> 50.91625 | CV14: 6 | CW14: =CR14*CS14*(CT14^2)*CV14 -> 149.32596 | DW14: Peso Propio = | DX14: 12 | DY14: =DY13 -> kg/m^2 | EG14: Condicion | EH14: Wb >= Wu | EN14: 1 | EO14: 0.9 CM + 1.43 CT | ES14: =0.9*ES10 -> 145.8 | ET14: kg | FJ14: Carga Puntual | FP14: Carga Puntual | FX14: critico | GH14: Carga Puntual | GN14: Carga Puntual | GV14: critico | HD14: Carga Puntual | HJ14: Carga Puntual | HP14: Carga Puntual | HV14: Carga Puntual | IJ14: =HC28 -> 901.28948 | IK14: 6 | IL14: =((IK14^2)+1)^0.5 -> 6.0827625 | IM14: =IJ14*IL14/1 -> 5482.3299 | IN14: =IM14/2500 -> 2.192932 | IO14: =IM14*IK14/IL14 -> 5407.7369 | IY14: Muros Tapón MT
BQ15: Se puese considerar que la villa se encuentra cercana a promontorios. Así mismo las torres, Casa Club y demás villas actuan en los vientos ocasionando un efectos de encajonamiento. | BY15: estas velocidades se emplearan para determinar la carga viva constante (viento promedio) y la maxima (rafagas) | CR15: 0.0048 | CS15: 2 | CT15: =CU9 -> 25.458125 | CV15: 6 | CW15: =CR15*CS15*(CT15^2)*CV15 -> 37.331489 | DW15: Carga Muerta Total = | DX15: =DX14+DX13 -> 112 | EG15: l = (120 Fb KS / Wu )^0.5 = | EH15: =(120*EH11*EH12/DX19)^0.5 -> 26.00623 | EI15: pulgadas | EN15: 2 | EO15: 1.4 CM | ES15: =1.4*ES10 -> 226.8 | ET15: kg | FJ15: Distancia de nudo a carga puntual | FL15: =-1*(IF(FL24=0,0,IF(FK15=0,0,IF(FK16=0,0,IF(FK15=(FL24/2),FK16*FL24/8,FK16*FK15*((FL24-FK15)*(FL24-FK15))/(FL24*FL24)))))) -> 0 | FM15: =IF(FL24=0,0,IF(FK15=0,0,IF(FK16=0,0,IF(FK15=(FL24/2),FL15*-1,FK16*(FK15*FK15)*(FL24-FK15)/(FL24*FL24))))) -> 0 | FP15: Distancia de nudo a carga puntual | FR15: =-1*(IF(FR24=0,0,IF(FQ15=0,0,IF(FQ16=0,0,IF(FQ15=(FR24/2),FQ16*FR24/8,FQ16*FQ15*((FR24-FQ15)*(FR24-FQ15))/(FR24*FR24)))))) -> 0 | FS15: =IF(FR24=0,0,IF(FQ15=0,0,IF(FQ16=0,0,IF(FQ15=(FR24/2),FR15*-1,FQ16*(FQ15*FQ15)*(FR24-FQ15)/(FR24*FR24))))) -> 0 | GH15: Distancia de nudo a carga puntual | GJ15: =-1*(IF(GJ24=0,0,IF(GI15=0,0,IF(GI16=0,0,IF(GI15=(GJ24/2),GI16*GJ24/8,GI16*GI15*((GJ24-GI15)*(GJ24-GI15))/(GJ24*GJ24)))))) -> 0 | GK15: =IF(GJ24=0,0,IF(GI15=0,0,IF(GI16=0,0,IF(GI15=(GJ24/2),GJ15*-1,GI16*(GI15*GI15)*(GJ24-GI15)/(GJ24*GJ24))))) -> 0 | GN15: Distancia de nudo a carga puntual | GP15: =-1*(IF(GP24=0,0,IF(GO15=0,0,IF(GO16=0,0,IF(GO15=(GP24/2),GO16*GP24/8,GO16*GO15*((GP24-GO15)*(GP24-GO15))/(GP24*GP24)))))) -> 0 | GQ15: =IF(GP24=0,0,IF(GO15=0,0,IF(GO16=0,0,IF(GO15=(GP24/2),GP15*-1,GO16*(GO15*GO15)*(GP24-GO15)/(GP24*GP24))))) -> 0 | HD15: Distancia de nudo a carga puntual | HF15: =-1*(IF(HF24=0,0,IF(HE15=0,0,IF(HE16=0,0,IF(HE15=(HF24/2),HE16*HF24/8,HE16*HE15*((HF24-HE15)*(HF24-HE15))/(HF24*HF24)))))) -> 0 | HG15: =IF(HF24=0,0,IF(HE15=0,0,IF(HE16=0,0,IF(HE15=(HF24/2),HF15*-1,HE16*(HE15*HE15)*(HF24-HE15)/(HF24*HF24))))) -> 0 | HJ15: Distancia de nudo a carga puntual | HL15: =-1*(IF(HL24=0,0,IF(HK15=0,0,IF(HK16=0,0,IF(HK15=(HL24/2),HK16*HL24/8,HK16*HK15*((HL24-HK15)*(HL24-HK15))/(HL24*HL24)))))) -> 0 | HM15: =IF(HL24=0,0,IF(HK15=0,0,IF(HK16=0,0,IF(HK15=(HL24/2),HL15*-1,HK16*(HK15*HK15)*(HL24-HK15)/(HL24*HL24))))) -> 0 | HP15: Distancia de nudo a carga puntual | HR15: =-1*(IF(HR24=0,0,IF(HQ15=0,0,IF(HQ16=0,0,IF(HQ15=(HR24/2),HQ16*HR24/8,HQ16*HQ15*((HR24-HQ15)*(HR24-HQ15))/(HR24*HR24)))))) -> 0 | HS15: =IF(HR24=0,0,IF(HQ15=0,0,IF(HQ16=0,0,IF(HQ15=(HR24/2),HR15*-1,HQ16*(HQ15*HQ15)*(HR24-HQ15)/(HR24*HR24))))) -> 0 | HV15: Distancia de nudo a carga puntual | HX15: =-1*(IF(HX24=0,0,IF(HW15=0,0,IF(HW16=0,0,IF(HW15=(HX24/2),HW16*HX24/8,HW16*HW15*((HX24-HW15)*(HX24-HW15))/(HX24*HX24)))))) -> 0 | HY15: =IF(HX24=0,0,IF(HW15=0,0,IF(HW16=0,0,IF(HW15=(HX24/2),HX15*-1,HW16*(HW15*HW15)*(HX24-HW15)/(HX24*HX24))))) -> 0 | IJ15: =HI28 -> 2452.7036 | IK15: 4 | IL15: =((IK15^2)+1)^0.5 -> 4.1231056 | IM15: =IJ15*IL15/1 -> 10112.756 | IN15: =IM15/2500 -> 4.0451023 | IO15: =IM15*IK15/IL15 -> 9810.8143 | IP15: critico | IY15: =EN24 -> Toda vez que no se generar ningun cambio en el entrepiso, ninguna redistribucion de esfuerzos, ni colocacion alguna de cargas concentradas en la losa de entrepiso no se requiere reanalizarle. En realidad aun con los voladizos proyectados las cargas sobre los muros de carga donde estos voladizos cargaran se veran disminuidas al eliminarse la techumbre original de concreto.
DJ16: PTR | DW16: Carga viva factorizada = | DX16: =DX12*1.6 -> 240 | EG16: ponderado | EH16: 12 | EI16: pulgadas | EJ16: =EH16*2.54 -> 30.48 | EK16: cm | EN16: 3 | EO16: 1.2 CM + 1.6 CV viento | ES16: =(1.2*ES10)+(1.6*ES11) -> 318.8383 | ET16: kg | FJ16: Carga Puntual | FP16: Carga Puntual | GH16: Carga Puntual | GN16: Carga Puntual | HD16: Carga Puntual | HJ16: Carga Puntual | HP16: Carga Puntual | HV16: Carga Puntual | IJ16: =HO28 -> 342.92116 | IK16: 2 | IL16: =((IK16^2)+1)^0.5 -> 2.236068 | IM16: =IJ16*IL16/1 -> 766.79502 | IN16: =IM16/2500 -> 0.30671801 | IO16: =IM16*IK16/IL16 -> 685.84232
L17: El complejo se encuentra en una zona de conglomerado marino y roca intrusiva (graniticas). Superficialmente recubierto con arenas por deposito eolico. An norte se aprecia el aluvion formado por el arroyo de El Descanso. Al oeste se aprecia una falla sin actividad a menos de 2 km situacion que es el promedio en toda la zona costera de Baja California. Por tanto tomaremos las prevenciones sismicas basicas que nos exige la normatividad del estado. | CH17: FL prom = | CI17: 0.0048 | CJ17: 2 | CK17: =CF11 -> 13.3308 | CM17: =CF46 -> 6 | CN17: =CI17*CJ17*(CK17^2)*CM17 -> 10.236109 | DW17: Carga muerta factorizada = | DX17: =DX15*1.4 -> 156.8 | EN17: 4 | EO17: 1.2 CM + 1.6 CV + .5 lluvia | ES17: =(1.2*ES10)+(1.6*ES9)+(0.5*ES12) -> 435.4 | ET17: kg | FJ17: Distancia de nudo a carga puntual | FL17: =-1*(IF(FL24=0,0,IF(FK17=0,0,IF(FK18=0,0,IF(FK17=(FL24/2),FK18*FL24/8,FK18*FK17*((FL24-FK17)*(FL24-FK17))/(FL24*FL24)))))) -> 0 | FM17: =IF(FL24=0,0,IF(FK17=0,0,IF(FK18=0,0,IF(FK17=(FL24/2),FL17*-1,FK18*(FK17*FK17)*(FL24-FK17)/(FL24*FL24))))) -> 0 | FP17: Distancia de nudo a carga puntual | FR17: =-1*(IF(FR24=0,0,IF(FQ17=0,0,IF(FQ18=0,0,IF(FQ17=(FR24/2),FQ18*FR24/8,FQ18*FQ17*((FR24-FQ17)*(FR24-FQ17))/(FR24*FR24)))))) -> 0 | FS17: =IF(FR24=0,0,IF(FQ17=0,0,IF(FQ18=0,0,IF(FQ17=(FR24/2),FR17*-1,FQ18*(FQ17*FQ17)*(FR24-FQ17)/(FR24*FR24))))) -> 0 | GH17: Distancia de nudo a carga puntual | GJ17: =-1*(IF(GJ24=0,0,IF(GI17=0,0,IF(GI18=0,0,IF(GI17=(GJ24/2),GI18*GJ24/8,GI18*GI17*((GJ24-GI17)*(GJ24-GI17))/(GJ24*GJ24)))))) -> 0 | GK17: =IF(GJ24=0,0,IF(GI17=0,0,IF(GI18=0,0,IF(GI17=(GJ24/2),GJ17*-1,GI18*(GI17*GI17)*(GJ24-GI17)/(GJ24*GJ24))))) -> 0 | GN17: Distancia de nudo a carga puntual | GP17: =-1*(IF(GP24=0,0,IF(GO17=0,0,IF(GO18=0,0,IF(GO17=(GP24/2),GO18*GP24/8,GO18*GO17*((GP24-GO17)*(GP24-GO17))/(GP24*GP24)))))) -> 0 | GQ17: =IF(GP24=0,0,IF(GO17=0,0,IF(GO18=0,0,IF(GO17=(GP24/2),GP17*-1,GO18*(GO17*GO17)*(GP24-GO17)/(GP24*GP24))))) -> 0 | HD17: Distancia de nudo a carga puntual | HF17: =-1*(IF(HF24=0,0,IF(HE17=0,0,IF(HE18=0,0,IF(HE17=(HF24/2),HE18*HF24/8,HE18*HE17*((HF24-HE17)*(HF24-HE17))/(HF24*HF24)))))) -> 0 | HG17: =IF(HF24=0,0,IF(HE17=0,0,IF(HE18=0,0,IF(HE17=(HF24/2),HF17*-1,HE18*(HE17*HE17)*(HF24-HE17)/(HF24*HF24))))) -> 0 | HJ17: Distancia de nudo a carga puntual | HL17: =-1*(IF(HL24=0,0,IF(HK17=0,0,IF(HK18=0,0,IF(HK17=(HL24/2),HK18*HL24/8,HK18*HK17*((HL24-HK17)*(HL24-HK17))/(HL24*HL24)))))) -> 0 | HM17: =IF(HL24=0,0,IF(HK17=0,0,IF(HK18=0,0,IF(HK17=(HL24/2),HL17*-1,HK18*(HK17*HK17)*(HL24-HK17)/(HL24*HL24))))) -> 0 | HP17: Distancia de nudo a carga puntual | HR17: =-1*(IF(HR24=0,0,IF(HQ17=0,0,IF(HQ18=0,0,IF(HQ17=(HR24/2),HQ18*HR24/8,HQ18*HQ17*((HR24-HQ17)*(HR24-HQ17))/(HR24*HR24)))))) -> 0 | HS17: =IF(HR24=0,0,IF(HQ17=0,0,IF(HQ18=0,0,IF(HQ17=(HR24/2),HR17*-1,HQ18*(HQ17*HQ17)*(HR24-HQ17)/(HR24*HR24))))) -> 0 | HV17: Distancia de nudo a carga puntual | HX17: =-1*(IF(HX24=0,0,IF(HW17=0,0,IF(HW18=0,0,IF(HW17=(HX24/2),HW18*HX24/8,HW18*HW17*((HX24-HW17)*(HX24-HW17))/(HX24*HX24)))))) -> 0 | HY17: =IF(HX24=0,0,IF(HW17=0,0,IF(HW18=0,0,IF(HW17=(HX24/2),HX17*-1,HW18*(HW17*HW17)*(HX24-HW17)/(HX24*HX24))))) -> 0 | IJ17: =HU28 -> 4585.6479 | IK17: 0 | IL17: =((IK17^2)+1)^0.5 -> 1 | IM17: =IJ17*IL17/1 -> 4585.6479 | IN17: =IM17/2500 -> 1.8342591 | IO17: =IM17*IK17/IL17 -> 0
AD18: Velocidad de Diseño. | BY18: Empuje Estatico por viento: | CH18: FL raf = | CI18: 0.0048 | CJ18: 2 | CK18: =CF13 -> 127.29062 | CM18: =CM17 -> 6 | CN18: =CI18*CJ18*(CK18^2)*CM18 -> 933.28723 | DJ18: Tensores | DW18: Carga Total = | DX18: =DX17+DX16 -> 396.8 | EF18: claro maximo por cortante | EN18: la formula 4 rige | ES18: =MAX(ES14:ES17) -> 435.4 | ET18: kg | FJ18: Carga Puntual | FP18: Carga Puntual | GH18: Carga Puntual | GN18: Carga Puntual | HD18: Carga Puntual | HJ18: Carga Puntual | HP18: Carga Puntual | HV18: Carga Puntual | KC18: Del Procedimiento de Construcción
U19: 2010 | AD19: Vß = K1 K2 Vo | BQ19: Claramente podemos apreciar que los vientos predominantes en la zona son de este a oeste y viceversa teniendo: | BY19: P = N C Vz² donde: P = presión o succión en kg/m² C = coeficiente de empuje 8 + a N = coeficiente de densidad del aire, igual a 0.0048 Vz = velocidad de diseño en km/h a = altura sobre el nivel del mar en km. | CH19: FL = FT | CP19: t= | CQ19: 0-->4 | CR19: To= | CS19: 1 | CU19: d= | CV19: 0.5 | DA19: elemento | DW19: Carga en lbs/pie2 = | DX19: =DX18*2.2/(3.28^2) -> 81.142177 | EG19: Ws = 20 Fs (lb/Q)/l2 | EN19: carga total techumbre: | ES19: =ES18 -> 435.4 | FJ19: Distancia de nudo a carga puntual | FL19: =-1*(IF(FL24=0,0,IF(FK19=0,0,IF(FK20=0,0,IF(FK19=(FL24/2),FK20*FL24/8,FK20*FK19*((FL24-FK19)*(FL24-FK19))/(FL24*FL24)))))) -> 0 | FM19: =IF(FL24=0,0,IF(FK19=0,0,IF(FK20=0,0,IF(FK19=(FL24/2),FL19*-1,FK20*(FK19*FK19)*(FL24-FK19)/(FL24*FL24))))) -> 0 | FP19: Distancia de nudo a carga puntual | FR19: =-1*(IF(FR24=0,0,IF(FQ19=0,0,IF(FQ20=0,0,IF(FQ19=(FR24/2),FQ20*FR24/8,FQ20*FQ19*((FR24-FQ19)*(FR24-FQ19))/(FR24*FR24)))))) -> 0 | FS19: =IF(FR24=0,0,IF(FQ19=0,0,IF(FQ20=0,0,IF(FQ19=(FR24/2),FR19*-1,FQ20*(FQ19*FQ19)*(FR24-FQ19)/(FR24*FR24))))) -> 0 | GH19: Distancia de nudo a carga puntual | GJ19: =-1*(IF(GJ24=0,0,IF(GI19=0,0,IF(GI20=0,0,IF(GI19=(GJ24/2),GI20*GJ24/8,GI20*GI19*((GJ24-GI19)*(GJ24-GI19))/(GJ24*GJ24)))))) -> 0 | GK19: =IF(GJ24=0,0,IF(GI19=0,0,IF(GI20=0,0,IF(GI19=(GJ24/2),GJ19*-1,GI20*(GI19*GI19)*(GJ24-GI19)/(GJ24*GJ24))))) -> 0 | GN19: Distancia de nudo a carga puntual | GP19: =-1*(IF(GP24=0,0,IF(GO19=0,0,IF(GO20=0,0,IF(GO19=(GP24/2),GO20*GP24/8,GO20*GO19*((GP24-GO19)*(GP24-GO19))/(GP24*GP24)))))) -> 0 | GQ19: =IF(GP24=0,0,IF(GO19=0,0,IF(GO20=0,0,IF(GO19=(GP24/2),GP19*-1,GO20*(GO19*GO19)*(GP24-GO19)/(GP24*GP24))))) -> 0 | HD19: Distancia de nudo a carga puntual | HF19: =-1*(IF(HF24=0,0,IF(HE19=0,0,IF(HE20=0,0,IF(HE19=(HF24/2),HE20*HF24/8,HE20*HE19*((HF24-HE19)*(HF24-HE19))/(HF24*HF24)))))) -> 0 | HG19: =IF(HF24=0,0,IF(HE19=0,0,IF(HE20=0,0,IF(HE19=(HF24/2),HF19*-1,HE20*(HE19*HE19)*(HF24-HE19)/(HF24*HF24))))) -> 0 | HJ19: Distancia de nudo a carga puntual | HL19: =-1*(IF(HL24=0,0,IF(HK19=0,0,IF(HK20=0,0,IF(HK19=(HL24/2),HK20*HL24/8,HK20*HK19*((HL24-HK19)*(HL24-HK19))/(HL24*HL24)))))) -> 0 | HM19: =IF(HL24=0,0,IF(HK19=0,0,IF(HK20=0,0,IF(HK19=(HL24/2),HL19*-1,HK20*(HK19*HK19)*(HL24-HK19)/(HL24*HL24))))) -> 0 | HP19: Distancia de nudo a carga puntual | HR19: =-1*(IF(HR24=0,0,IF(HQ19=0,0,IF(HQ20=0,0,IF(HQ19=(HR24/2),HQ20*HR24/8,HQ20*HQ19*((HR24-HQ19)*(HR24-HQ19))/(HR24*HR24)))))) -> 0 | HS19: =IF(HR24=0,0,IF(HQ19=0,0,IF(HQ20=0,0,IF(HQ19=(HR24/2),HR19*-1,HQ20*(HQ19*HQ19)*(HR24-HQ19)/(HR24*HR24))))) -> 0 | HV19: Distancia de nudo a carga puntual | HX19: =-1*(IF(HX24=0,0,IF(HW19=0,0,IF(HW20=0,0,IF(HW19=(HX24/2),HW20*HX24/8,HW20*HW19*((HX24-HW19)*(HX24-HW19))/(HX24*HX24)))))) -> 0 | HY19: =IF(HX24=0,0,IF(HW19=0,0,IF(HW20=0,0,IF(HW19=(HX24/2),HX19*-1,HW20*(HW19*HW19)*(HX24-HW19)/(HX24*HX24))))) -> 0 | IK19: Angulo | IL19: 2 x 1/4 | IY19: Trabes T1 | KC19: Se procurara colar Monolíticamente Trabes Losas y Columnas en cada nivel. Particularmente en el nivel sótano para evitar juntas frías que conduzcan a filtraciones. Se empleara Block dala para colocar la varilla horizontal . Para ganchos y traslapes referirse a manual ACI.
AD20: 1.15 | AE20: K1= | AF20: factor de topografia se tomara 1 para terreno plano y 1.15 en promontonrios, centros industriales y residenciales | CP20: p \/ | CQ20: v \/ t= | CR20: 0 | CS20: 1 | CT20: 2 | CU20: 3 | CV20: 4 | CW20: Ck= | CX20: C= | CY20: T= | CZ20: d= | DA20: l= | DB20: Periodo | DD20: Condicion: | DW20: peso tablaroca = | DX20: 6.75 | DY20: m^2 | EG20: Ws = maxima carga uniforme por cortante | EN20: carga total techumbre en ton: | ES20: =ES19/1000 -> 0.4354 | FJ20: Carga Puntual | FP20: Carga Puntual | GH20: Carga Puntual | GN20: Carga Puntual | HD20: Carga Puntual | HJ20: Carga Puntual | HP20: Carga Puntual | HV20: Carga Puntual | IK20: Canal | IL20: 3 x 4.1 | IY20: Trabe de 60 x 35 cm armada con 3 Varillas #5 en cada lecho, dos varillas # 4 al centro, Estribos #3 @ 20 al centro y @ 15 a 1/4 de L en cada extremo así como como a 70 cm de cada nodo interno (donde reciba otra trabe)
CP21: =CW11 -> 933.28723 | CQ21: =CW5 -> 77.773935 | CR21: =CP21*(CW21/CX21)*CZ21*(SIN(2*PI()*CR20/CY21)) -> 0 | CS21: =CP21*(CW21/CX21)*CZ21*(SIN(2*PI()*CS20/CY21)) -> -213.1952 | CT21: =CP21*(CW21/CX21)*CZ21*(SIN(2*PI()*CT20/CY21)) -> 268.58238 | CU21: =CP21*(CW21/CX21)*CZ21*(SIN(2*PI()*CU20/CY21)) -> -125.1637 | CV21: =CP21*(CW21/CX21)*CZ21*(SIN(2*PI()*CV20/CY21)) -> -110.9017 | CW21: 1 | CX21: 1.7 | CY21: =18*(CZ21/CQ21) -> 0.11572 | CZ21: =CV19 -> 0.5 | DA21: 4.1 | DB21: =2*PI()*((DA21/9.81)^0.5) -> 4.0619754 | DD21: Se desea ampliar la recámara principal de una de la villas. Paralelamente el dueño desea cambiar el diseño a fin de obtener un cancel similar al de los condominios (1,4) sin obstrucción alguna a la vista. Esto significa que la techumbre de la recámara estará sobre algún tipo de estructura en voladizo con un largo máximo de poco menos de 6 metros. | DW21: cargas entrepiso= | DX21: =DX18 -> 396.8 | EG21: Fs = esfuerzo cortante maximo permisible | FJ21: Distancia de nudo a carga puntual | FL21: =-1*(IF(FL24=0,0,IF(FK21=0,0,IF(FK22=0,0,IF(FK21=(FL24/2),FK22*FL24/8,FK22*FK21*((FL24-FK21)*(FL24-FK21))/(FL24*FL24)))))) -> 0 | FM21: =IF(FL24=0,0,IF(FK21=0,0,IF(FK22=0,0,IF(FK21=(FL24/2),FL21*-1,FK22*(FK21*FK21)*(FL24-FK21)/(FL24*FL24))))) -> 0 | FP21: Distancia de nudo a carga puntual | FR21: =-1*(IF(FR24=0,0,IF(FQ21=0,0,IF(FQ22=0,0,IF(FQ21=(FR24/2),FQ22*FR24/8,FQ22*FQ21*((FR24-FQ21)*(FR24-FQ21))/(FR24*FR24)))))) -> 0 | FS21: =IF(FR24=0,0,IF(FQ21=0,0,IF(FQ22=0,0,IF(FQ21=(FR24/2),FR21*-1,FQ22*(FQ21*FQ21)*(FR24-FQ21)/(FR24*FR24))))) -> 0 | GH21: Distancia de nudo a carga puntual | GJ21: =-1*(IF(GJ24=0,0,IF(GI21=0,0,IF(GI22=0,0,IF(GI21=(GJ24/2),GI22*GJ24/8,GI22*GI21*((GJ24-GI21)*(GJ24-GI21))/(GJ24*GJ24)))))) -> 0 | GK21: =IF(GJ24=0,0,IF(GI21=0,0,IF(GI22=0,0,IF(GI21=(GJ24/2),GJ21*-1,GI22*(GI21*GI21)*(GJ24-GI21)/(GJ24*GJ24))))) -> 0 | GN21: Distancia de nudo a carga puntual | GP21: =-1*(IF(GP24=0,0,IF(GO21=0,0,IF(GO22=0,0,IF(GO21=(GP24/2),GO22*GP24/8,GO22*GO21*((GP24-GO21)*(GP24-GO21))/(GP24*GP24)))))) -> 0 | GQ21: =IF(GP24=0,0,IF(GO21=0,0,IF(GO22=0,0,IF(GO21=(GP24/2),GP21*-1,GO22*(GO21*GO21)*(GP24-GO21)/(GP24*GP24))))) -> 0 | HD21: Distancia de nudo a carga puntual | HF21: =-1*(IF(HF24=0,0,IF(HE21=0,0,IF(HE22=0,0,IF(HE21=(HF24/2),HE22*HF24/8,HE22*HE21*((HF24-HE21)*(HF24-HE21))/(HF24*HF24)))))) -> 0 | HG21: =IF(HF24=0,0,IF(HE21=0,0,IF(HE22=0,0,IF(HE21=(HF24/2),HF21*-1,HE22*(HE21*HE21)*(HF24-HE21)/(HF24*HF24))))) -> 0 | HJ21: Distancia de nudo a carga puntual | HL21: =-1*(IF(HL24=0,0,IF(HK21=0,0,IF(HK22=0,0,IF(HK21=(HL24/2),HK22*HL24/8,HK22*HK21*((HL24-HK21)*(HL24-HK21))/(HL24*HL24)))))) -> 0 | HM21: =IF(HL24=0,0,IF(HK21=0,0,IF(HK22=0,0,IF(HK21=(HL24/2),HL21*-1,HK22*(HK21*HK21)*(HL24-HK21)/(HL24*HL24))))) -> 0 | HP21: Distancia de nudo a carga puntual | HR21: =-1*(IF(HR24=0,0,IF(HQ21=0,0,IF(HQ22=0,0,IF(HQ21=(HR24/2),HQ22*HR24/8,HQ22*HQ21*((HR24-HQ21)*(HR24-HQ21))/(HR24*HR24)))))) -> 0 | HS21: =IF(HR24=0,0,IF(HQ21=0,0,IF(HQ22=0,0,IF(HQ21=(HR24/2),HR21*-1,HQ22*(HQ21*HQ21)*(HR24-HQ21)/(HR24*HR24))))) -> 0 | HV21: Distancia de nudo a carga puntual | HX21: =-1*(IF(HX24=0,0,IF(HW21=0,0,IF(HW22=0,0,IF(HW21=(HX24/2),HW22*HX24/8,HW22*HW21*((HX24-HW21)*(HX24-HW21))/(HX24*HX24)))))) -> 0 | HY21: =IF(HX24=0,0,IF(HW21=0,0,IF(HW22=0,0,IF(HW21=(HX24/2),HX21*-1,HW22*(HW21*HW21)*(HX24-HW21)/(HX24*HX24))))) -> 0
BU22: Promedio NASA | CP22: =CW12 -> 597.30382 | CQ22: =CW6 -> 49.775319 | CR22: =CP22*(CW22/CX22)*CZ22*(SIN(2*PI()*CR21/CY22)) -> 0 | CS22: =CP22*(CW22/CX22)*CZ22*(SIN(2*PI()*CS21/CY22)) -> -150.28675 | CT22: =CP22*(CW22/CX22)*CZ22*(SIN(2*PI()*CT21/CY22)) -> -35.515322 | CU22: =CP22*(CW22/CX22)*CZ22*(SIN(2*PI()*CU21/CY22)) -> 110.40683 | CV22: =CP22*(CW22/CX22)*CZ22*(SIN(2*PI()*CV21/CY22)) -> -133.66207 | CW22: =CW21 -> 1 | CX22: =CX21 -> 1.7 | CY22: =CY21 -> 0.11572 | CZ22: =CZ21 -> 0.5 | DA22: 4 | DB22: =2*PI()*((DA22/9.81)^0.5) -> 4.0121334 | DW22: reacciones= | DX22: =DX21*DW42/3.28 -> 362.92683 | EG22: Ib/Q = constante para cortante por seccion | EN22: Entrepiso | FF22: long | FG22: 3 | FJ22: Carga Puntual | FP22: Carga Puntual | FW22: long. | GD22: long | GE22: 1 | GH22: Carga Puntual | GN22: Carga Puntual | GU22: long. | GZ22: long | HD22: Carga Puntual | HJ22: Carga Puntual | HP22: Carga Puntual | HV22: Carga Puntual | IC22: long. | IK22: Perfil Principal
AD23: 1.15 | AE23: K2= | AF23: factor de recurrencia se tomara 1 para estructuras tipo B y 1.15 para estructuras tipo A | BU23: De | CP23: =CW13 -> 335.9834 | CQ23: =CW7 -> 27.998617 | CR23: =CP23*(CW23/CX23)*CZ23*(SIN(2*PI()*CR22/CY23)) -> 0 | CS23: =CP23*(CW23/CX23)*CZ23*(SIN(2*PI()*CS22/CY23)) -> 95.751755 | CT23: =CP23*(CW23/CX23)*CZ23*(SIN(2*PI()*CT22/CY23)) -> 54.319918 | CU23: =CP23*(CW23/CX23)*CZ23*(SIN(2*PI()*CU22/CY23)) -> 50.7947 | CV23: =CP23*(CW23/CX23)*CZ23*(SIN(2*PI()*CV22/CY23)) -> -28.892776 | CW23: =CW22 -> 1 | CX23: =CX22 -> 1.7 | CY23: =CY22 -> 0.11572 | CZ23: =CZ22 -> 0.5 | DA23: 3.8 | DB23: =2*PI()*((DA23/9.81)^0.5) -> 3.9105439 | DW23: area req | DX23: =DX22/EA32 -> 0.17038818 | DY23: cm2 | EG23: l = claro entre soportes | FF23: w | FG23: =FG6*FG7 -> 1756.2 | FK23: Momento total en Nudos = suma. | FL23: =SUM(FL9:FL22) -> -1361.8773 | FM23: =SUM(FM9:FM22) -> 1361.8773 | FQ23: Momento total en Nudos = suma. | FR23: =SUM(FR9:FR22) -> 0 | FS23: =SUM(FS9:FS22) -> 0 | FW23: w | GD23: w | GE23: =GE6*GE7 -> 1756.2 | GI23: Momento total en Nudos = suma. | GJ23: =SUM(GJ9:GJ22) -> -1361.8773 | GK23: =SUM(GK9:GK22) -> 1361.8773 | GO23: Momento total en Nudos = suma. | GP23: =SUM(GP9:GP22) -> -1361.8773 | GQ23: =SUM(GQ9:GQ22) -> 1361.8773 | GU23: w | GZ23: w | HE23: Momento total en Nudos = suma. | HF23: =SUM(HF9:HF22) -> -173.89072 | HG23: =SUM(HG9:HG22) -> 153.82759 | HK23: Momento total en Nudos = suma. | HL23: =SUM(HL9:HL22) -> -151.3197 | HM23: =SUM(HM9:HM22) -> 151.3197 | HQ23: Momento total en Nudos = suma. | HR23: =SUM(HR9:HR22) -> -151.3197 | HS23: =SUM(HS9:HS22) -> 151.3197 | HW23: Momento total en Nudos = suma. | HX23: =SUM(HX9:HX22) -> -1361.8773 | HY23: =SUM(HY9:HY22) -> 1361.8773 | IC23: w | IK23: Momento | IL23: Mom kg-cm | IM23: Cortante | IN23: Z req | IO23: Area Req Vy | IY23: Trabe T2 | KC23: Materiales de Construcción
L24: Mecanica de Suelos Estimada | BU24: 3.2 | BV24: m/s | CP24: =CW14 -> 149.32596 | CQ24: =CW8 -> 12.44383 | CR24: =CP24*(CW24/CX24)*CZ24*(SIN(2*PI()*CR23/CY24)) -> 0 | CS24: =CP24*(CW24/CX24)*CZ24*(SIN(2*PI()*CS23/CY24)) -> 15.286476 | CT24: =CP24*(CW24/CX24)*CZ24*(SIN(2*PI()*CT23/CY24)) -> 23.951787 | CU24: =CP24*(CW24/CX24)*CZ24*(SIN(2*PI()*CU23/CY24)) -> -14.913237 | CV24: =CP24*(CW24/CX24)*CZ24*(SIN(2*PI()*CV23/CY24)) -> 39.539617 | CW24: =CW23 -> 1 | CX24: =CX23 -> 1.7 | CY24: =CY23 -> 0.11572 | CZ24: =CZ23 -> 0.5 | DA24: 2.2 | DB24: =2*PI()*((DA24/9.81)^0.5) -> 2.9754777 | DU24: Wux | EG24: =EG10 -> para triplay de 1" estructural | EN24: Toda vez que no se generar ningun cambio en el entrepiso, ninguna redistribucion de esfuerzos, ni colocacion alguna de cargas concentradas en la losa de entrepiso no se requiere reanalizarle. En realidad aun con los voladizos proyectados las cargas sobre los muros de carga donde estos voladizos cargaran se veran disminuidas al eliminarse la techumbre original de concreto. | FJ24: =FI24+FH25+FI26+FJ25 -> -0.5 | FK24: 1 | FL24: 3 | FP24: =FO24+FN25+FO26+FP25 -> 0 | FQ24: 3 | FV24: =FU24+FT25+FU26+FV25 -> 0 | FX24: =FX23*FX22 -> 0 | GH24: =GG24+GF25+GG26+GH25 -> -0.5 | GJ24: 3 | GN24: =GM24+GL25+GM26+GN25 -> -0.5 | GO24: 1 | GP24: 3 | GT24: =GS24+GR25+GS26+GT25 -> 0 | GV24: =GV23*GV22 -> 0 | HD24: =HC24+HB25+HC26+HD25 -> -0.5 | HF24: 1 | HG24: 0 | HJ24: =HI24+HH25+HI26+HJ25 -> -0.5 | HL24: 1 | HP24: =HO24+HN25+HO26+HP25 -> -0.5 | HR24: 1 | HS24: 0 | HV24: =HU24+HT25+HU26+HV25 -> -0.5 | HW24: 1 | HX24: 3 | HY24: 0 | IB24: =IA24+HZ25+IA26+IB25 -> 0 | ID24: =ID23*ID22 -> 0 | IJ24: voladizo | IK24: =FH42 -> 8111.8909 | IL24: =IK24*100 -> 811189.09 | IM24: =FH47 -> 2961.8227 | IN24: =IL24/2500 -> 324.47564 | IO24: =IM24/2500 -> 1.1847291 | IP24: critico | IY24: =#REF! -> #REF! | KC24: Block
L25: No contamos con un estudio de mecanica de suelos sin embargo sabemos que en el lugar se encontraron arenas por tanto se tomaran estos datos para la evaluacion sismica. | AE25: Vo= | AF25: velocidad de viento regional | BU25: =BU24*3600/1000 -> 11.52 | BV25: km/hra | CP25: =CW15 -> 37.331489 | CQ25: =CW9 -> 3.1109574 | CR25: =CP25*(CW25/CX25)*CZ25*(SIN(2*PI()*CR24/CY25)) -> 0 | CS25: =CP25*(CW25/CX25)*CZ25*(SIN(2*PI()*CS24/CY25)) -> 6.3877911 | CT25: =CP25*(CW25/CX25)*CZ25*(SIN(2*PI()*CT24/CY25)) -> -1.3399552 | CU25: =CP25*(CW25/CX25)*CZ25*(SIN(2*PI()*CU24/CY25)) -> 7.8385378 | CV25: =CP25*(CW25/CX25)*CZ25*(SIN(2*PI()*CV24/CY25)) -> -10.035749 | CW25: =CW24 -> 1 | CX25: =CX24 -> 1.7 | CY25: =CY24 -> 0.11572 | CZ25: =CZ24 -> 0.5 | DA25: 2 | DB25: =2*PI()*((DA25/9.81)^0.5) -> 2.8370067 | EG25: Fs = | EH25: 48 | EI25: lbs/plg^2 | FF25: momento | FG25: =(FG23*FG22*FG22/2)+(FG9*FG22/4) -> 8111.8909 | FI25: =FG25+FK25 -> 6750.0136 | FJ25: =IF(FL26=0,0,IF(FK24=3,0,IF(FM24=3,0,IF(FM24=2,-0.5,IF(FM24=1,0,-0.5))))) -> -0.5 | FK25: =FL23 -> -1361.8773 | FL25: 1 | FM25: =FM23 -> 1361.8773 | FN25: =IF(FL26=0,0,IF(FM24=3,0,IF(FK24=3,0,IF(FK24=2,-0.5,IF(FK24=1,0,(FL26/(FL26+FR26))*(-0.5)))))) -> 0 | FO25: =IF(FL24=0,FM26+FQ25,IF(FR24=0,FQ26+FM25,FM25+FQ25)) -> 1361.8773 | FP25: =IF(FR26=0,0,IF(FQ24=3,0,IF(FS24=3,0,IF(FS24=2,-0.5,IF(FS24=1,0,(FR26/(FR26+FL26))*(-0.5)))))) -> 0 | FQ25: =FR23 -> 0 | FR25: =FL25 -> 1 | FS25: =FS23 -> 0 | FT25: =IF(FR26=0,0,IF(FS24=3,0,IF(FQ24=3,0,IF(FQ24=2,-0.5,IF(FQ24=1,0,-0.5))))) -> 0 | FU25: =FS25+FW25 -> 0 | FW25: 0 | GD25: momento | GE25: =(GE23*GE22*GE22/2)+(GE9*GE22/4) -> 947.76364 | GG25: =GE25+GI25 -> -414.11364 | GH25: =IF(GJ26=0,0,IF(GI24=3,0,IF(GK24=3,0,IF(GK24=2,-0.5,IF(GK24=1,0,-0.5))))) -> -0.5 | GI25: =GJ23 -> -1361.8773 | GJ25: 1 | GK25: =GK23 -> 1361.8773 | GL25: =IF(GJ26=0,0,IF(GK24=3,0,IF(GI24=3,0,IF(GI24=2,-0.5,IF(GI24=1,0,(GJ26/(GJ26+GP26))*(-0.5)))))) -> -0.25 | GM25: =IF(GJ24=0,GK26+GO25,IF(GP24=0,GO26+GK25,GK25+GO25)) -> 0 | GN25: =IF(GP26=0,0,IF(GO24=3,0,IF(GQ24=3,0,IF(GQ24=2,-0.5,IF(GQ24=1,0,(GP26/(GP26+GJ26))*(-0.5)))))) -> -0.25 | GO25: =GP23 -> -1361.8773 | GP25: =GJ25 -> 1 | GQ25: =GQ23 -> 1361.8773 | GR25: =IF(GP26=0,0,IF(GQ24=3,0,IF(GO24=3,0,IF(GO24=2,-0.5,IF(GO24=1,0,-0.5))))) -> 0 | GS25: =GQ25+GU25 -> 1361.8773 | GU25: 0 | GZ25: momento | HC25: =HA25+HE25 -> -173.89072 | HD25: =IF(HF26=0,0,IF(HE24=3,0,IF(HG24=3,0,IF(HG24=2,-0.5,IF(HG24=1,0,-0.5))))) -> -0.5 | HE25: =HF23 -> -173.89072 | HF25: 1 | HG25: =HG23 -> 153.82759 | HH25: =IF(HF26=0,0,IF(HG24=3,0,IF(HE24=3,0,IF(HE24=2,-0.5,IF(HE24=1,0,(HF26/(HF26+HL26))*(-0.5)))))) -> -0.25 | HI25: =IF(HF24=0,HG26+HK25,IF(HL24=0,HK26+HG25,HG25+HK25)) -> 2.5078909 | HJ25: =IF(HL26=0,0,IF(HK24=3,0,IF(HM24=3,0,IF(HM24=2,-0.5,IF(HM24=1,0,(HL26/(HL26+HF26))*(-0.5)))))) -> -0.25 | HK25: =HL23 -> -151.3197 | HL25: 1 | HM25: =HM23 -> 151.3197 | HN25: =IF(HL26=0,0,IF(HM24=3,0,IF(HK24=3,0,IF(HK24=2,-0.5,IF(HK24=1,0,(HL26/(HL26+HR26))*(-0.5)))))) -> -0.25 | HO25: =IF(HL24=0,HM26+HQ25,IF(HR24=0,HQ26+HM25,HM25+HQ25)) -> 0 | HP25: =IF(HR26=0,0,IF(HQ24=3,0,IF(HS24=3,0,IF(HS24=2,-0.5,IF(HS24=1,0,(HR26/(HR26+HL26))*(-0.5)))))) -> -0.25 | HQ25: =HR23 -> -151.3197 | HR25: 1 | HS25: =HS23 -> 151.3197 | HT25: =IF(HR26=0,0,IF(HS24=3,0,IF(HQ24=3,0,IF(HQ24=2,-0.5,IF(HQ24=1,0,(HR26/(HR26+HX26))*(-0.5)))))) -> -0.375 | HU25: =IF(HR24=0,HS26+HW25,IF(HX24=0,HW26+HS25,HS25+HW25)) -> -1210.5576 | HV25: =IF(HX26=0,0,IF(HW24=3,0,IF(HY24=3,0,IF(HY24=2,-0.5,IF(HY24=1,0,(HX26/(HX26+HR26))*(-0.5)))))) -> -0.125 | HW25: =HX23 -> -1361.8773 | HX25: =HR25 -> 1 | HY25: =HY23 -> 1361.8773 | HZ25: =IF(HX26=0,0,IF(HY24=3,0,IF(HW24=3,0,IF(HW24=2,-0.5,IF(HW24=1,0,-0.5))))) -> 0 | IA25: =HY25+IC25 -> 1361.8773 | IC25: 0 | IJ25: semiarriostrado | IK25: =GF42 -> 1480.1955 | IL25: =IK25*100 -> 148019.55 | IM25: =GF47 -> 2961.8227 | IN25: =IL25/2500 -> 59.207818 | IO25: =IM25/2500 -> 1.1847291 | KC25: Block 1= Block Estructural 20x40, en todo caso en que se deban construir muros confinados se empleara este block. Para muros de relleno o muros pantalla se puede emplear block o tabique a elección del contratista. En ningún momento se ataran los muro pantalla a la estructura debiendo dejar una junta constructiva de mínimo 1/2" sellada con sicaflex o algún producto similar. En caso de desear modificar algún muro pantalla para integrarlo a la estructura favor de consultar primero para verificar los efectos sobre los marcos.
AD26: encontramos la siguiente roseta de los vientos para esta zona . | BU26: Promedio SAHOPE | BY26: Para paredes aisladas y anuncios C= | CC26: 1 | DX26: Wuy =Wux*.25 | EG26: Ib/Q = | EH26: 6.762 | EI26: plg^2/pie | FL26: =IF(FL24=0,0,FL25/FL24) -> 0.33333333 | FR26: =IF(FR24=0,0,FR25/FR24) -> 0 | GJ26: =IF(GJ24=0,0,GJ25/GJ24) -> 0.33333333 | GP26: =IF(GP24=0,0,GP25/GP24) -> 0.33333333 | HF26: =IF(HF24=0,0,HF25/HF24) -> 1 | HL26: =IF(HL24=0,0,HL25/HL24) -> 1 | HR26: =IF(HR24=0,0,HR25/HR24) -> 1 | HX26: =IF(HX24=0,0,HX25/HX24) -> 0.33333333 | IJ26: arriostrado | IK26: =HB42 -> 1529.2334 | IL26: =IK26*100 -> 152923.34 | IM26: =HB47 -> 2735.3075 | IN26: =IL26/2500 -> 61.169335 | IO26: =IM26/2500 -> 1.094123
BU27: De | BY27: P prom = | BZ27: =0.0048 -> 0.0048 | CA27: x | CB27: =CC26 -> 1 | CC27: x | CD27: =CF11 -> 13.3308 | CE27: ^2 = | CF27: =BZ27*CB27*(CD27^2) -> 0.8530091 | DD27: Solución | EG27: Condicion | EI27: Ws > = Wu | FF27: voladizo | FG27: =FG22*FG23 -> 5268.6 | FI27: =FG27 -> 5268.6 | FJ27: =(FI25+FN27)*FJ25 -> -3375.0068 | FL27: momento puro: | FM27: =FK7 -> 0 | FN27: =(FO25)*FN25 -> 0 | FO27: reacción | FP27: =(FO25)*FP25 -> 0 | FR27: momento puro: | FS27: =FQ7 -> 0 | FT27: =(FU25+FP27)*FT25 -> 0 | FU27: =FX24 -> 0 | GD27: voladizo | GE27: =GE22*GE23 -> 1756.2 | GG27: =GE27 -> 1756.2 | GH27: =(GG25+GL27)*GH25 -> 207.05682 | GJ27: momento puro: | GK27: =GI7 -> 0 | GL27: =(GM25)*GL25 -> 0 | GM27: reacción | GN27: =(GM25)*GN25 -> 0 | GP27: momento puro: | GQ27: =GO7 -> 0 | GR27: =(GS25+GN27)*GR25 -> 0 | GS27: =GV24 -> 0 | GZ27: voladizo | HA27: =HA22*HA23 -> 0 | HC27: =HA27 -> 0 | HD27: =(HC25+HH27)*HD25 -> 73.072622 | HF27: momento puro: | HG27: =HE7 -> 0 | HH27: =(HI25+HN27)*HH25 -> 27.74547 | HI27: reacción | HJ27: =(HI25+HN27)*HJ25 -> 27.74547 | HL27: momento puro: | HM27: =HK7 -> 0 | HN27: =(HO25+HT27)*HN25 -> -113.48977 | HO27: reacción | HP27: =(HO25+HT27)*HP25 -> -113.48977 | HR27: momento puro: | HS27: =HQ7 -> 0 | HT27: =(HU25)*HT25 -> 453.95909 | HU27: reacción | HV27: =(HU25)*HV25 -> 151.3197 | HX27: momento puro: | HY27: =HW7 -> 0 | HZ27: =(IA25+HV27)*HZ25 -> 0 | IA27: =ID24 -> 0
L28: Suelo Arenoso | AH28: Los Valores aqui mostrados nos dan una idea de los vientos tipicos. 8.8 m/s = 31.68 km/hra, sin embargo, tanto por observaciones propias como por los minimos que nos pide Reglamento de la Ley de Edificaciones del Estado de Baja California sabemos que podemos tener rafagas mucho muy superiores. Tenemos registradas por medicion directa velocidades de rafaga de hasta 110 km/hra. La CFE nos propone 125 km/hra. Por lo tanto emplearemos esta roseta para proponer una carga viva adicional, constante y emplearemos el valor de rafaga para el analisis por viento. | BU28: 1.7 | BV28: m/s | CH28: F= Fuerza | CJ28: CK= coheficiente por VzD | CM28: t= tiempo | DD28: En primero término se le recomendó al cliente demoler la techumbre original toda vez que esta es de losa inclincada de concreto de 10 cm y teja. Esto debido a que en primer lugar, realizar cortes y ampliaciones en concreto generaria juntas frias, en segundo lugar no podriamos preservar el mismo concepto arquitectonico si tuvieremos un pedazo de techo al que se le agrego otro; y finalmente, estariamos cargando con un peso muerto innecesario y esto sobre una estructura en voladizo. Aun cuando es realativamente sencillo diseñar una trabe lo suficientemente aperaltada para resistir un peso dado (por elevado que sea ) dejar cargas elevadas, asimetricas, en estructuras en voladizo es sumamente peligros ante efectos sismicos. | EC28: Mu=WxL^2 / 32 | EG28: =DW19 -> Carga en lbs/pie2 = | EH28: =DX19 -> 81.142177 | FH28: reacciones en el nudo | FI28: =FK38+FG27 -> 11367.361 | FJ28: =(FI25+FN28)*FJ25 -> -3375.0068 | FK28: =IF(FL24=0,0,IF(FM27=0,0,-1*(FM27/FL24))) -> 0 | FL28: reacciones | FM28: =IF(FL24=0,0,IF(FM27=0,0,FM27/FL24)) -> 0 | FN28: =(FO25+FJ27+FT27)*FN25 -> 0 | FO28: =IF(FL24=0,FQ38+FM39,IF(FR24=0,FQ39+FM38,FM38+FQ38)) -> -651.25227 | FP28: =(FO25+FJ27+FT27)*FP25 -> 0 | FQ28: =IF(FR24=0,0,IF(FS27=0,0,-1*(FS27/FR24))) -> 0 | FR28: reacciones | FS28: =IF(FR24=0,0,IF(FS27=0,0,FS27/FR24)) -> 0 | FT28: =(FU25+FP28)*FT25 -> 0 | FU28: =FS38+FU27 -> 0 | FV28: Cortante en el nudo | GF28: reacciones en el nudo | GG28: =GI38+GE27 -> 4302.4773 | GH28: =(GG25+GL28)*GH25 -> 232.93892 | GI28: =IF(GJ24=0,0,IF(GK27=0,0,-1*(GK27/GJ24))) -> 0 | GJ28: reacciones | GK28: =IF(GJ24=0,0,IF(GK27=0,0,GK27/GJ24)) -> 0 | GL28: =(GM25+GH27+GR27)*GL25 -> -51.764205 | GM28: =IF(GJ24=0,GO38+GK39,IF(GP24=0,GO39+GK38,GK38+GO38)) -> 5684.1455 | GN28: =(GM25+GH27+GR27)*GN25 -> -51.764205 | GO28: =IF(GP24=0,0,IF(GQ27=0,0,-1*(GQ27/GP24))) -> 0 | GP28: reacciones | GQ28: =IF(GP24=0,0,IF(GQ27=0,0,GQ27/GP24)) -> 0 | GR28: =(GS25+GN28)*GR25 -> 0 | GS28: =GQ38+GS27 -> 2664.5955 | GT28: Cortante en el nudo | HB28: reacciones en el nudo | HC28: =HE38+HA27 -> 901.28948 | HD28: =(HC25+HH28)*HD25 -> 80.009696 | HE28: =IF(HF24=0,0,IF(HG27=0,0,-1*(HG27/HF24))) -> 0 | HF28: reacciones | HG28: =IF(HF24=0,0,IF(HG27=0,0,HG27/HF24)) -> 0 | HH28: =(HI25+HD27+HN28)*HH25 -> 13.871323 | HI28: =IF(HF24=0,HK38+HG39,IF(HL24=0,HK39+HG38,HG38+HK38)) -> 2452.7036 | HJ28: =(HI25+HD27+HN28)*HJ25 -> 13.871323 | HK28: =IF(HL24=0,0,IF(HM27=0,0,-1*(HM27/HL24))) -> 0 | HL28: reacciones | HM28: =IF(HL24=0,0,IF(HM27=0,0,HM27/HL24)) -> 0 | HN28: =(HO25+HJ27+HT28)*HN25 -> -131.06581 | HO28: =IF(HL24=0,HQ38+HM39,IF(HR24=0,HQ39+HM38,HM38+HQ38)) -> 342.92116 | HP28: =(HO25+HJ27+HT28)*HP25 -> -131.06581 | HQ28: =IF(HR24=0,0,IF(HS27=0,0,-1*(HS27/HR24))) -> 0 | HR28: reacciones | HS28: =IF(HR24=0,0,IF(HS27=0,0,HS27/HR24)) -> 0 | HT28: =(HU25+HP27+HZ27)*HT25 -> 496.51776 | HU28: =IF(HR24=0,HW38+HS39,IF(HX24=0,HW39+HS38,HS38+HW38)) -> 4585.6479 | HV28: =(HU25+HP27+HZ27)*HV25 -> 165.50592 | HW28: =IF(HX24=0,0,IF(HY27=0,0,-1*(HY27/HX24))) -> 0 | HX28: reacciones | HY28: =IF(HX24=0,0,IF(HY27=0,0,HY27/HX24)) -> 0 | HZ28: =(IA25+HV28)*HZ25 -> 0 | IA28: =HY38+IA27 -> 2891.1106 | IB28: Cortante en el nudo | IK28: Efecto Rafaga = Impacto | IM28: Z req | IN28: =IN24 -> 324.47564 | IO28: x 3 = | IP28: =IN28*3 -> 973.42691
B29: Ingeniero Calculista | L29: Caracteristicas Promedio | BU29: =BU28*3600/1000 -> 6.12 | BV29: km/hra | BY29: P rafa = | BZ29: =BZ27 -> 0.0048 | CA29: x | CB29: =CB27 -> 1 | CC29: x | CD29: =CF13 -> 127.29062 | CE29: ^2 = | CF29: =BZ29*CB29*(CD29^2) -> 77.773935 | CH29: p= presion de diseno | CJ29: C: Coheficiente empuje | CM29: T= periodo alternante ( 18 d/v) | EH29: l = 20 Fs (Ib/Q) / Wu = | EI29: =(20*EH25*EH26/EH28) -> 80.001797 | EJ29: pulgadas | FJ29: =(FI25+FN29)*FJ25 -> -3375.0068 | FL29: Reacciones por cargas | FN29: =(FO25+FJ28+FT28)*FN25 -> 0 | FP29: =(FO25+FJ28+FT28)*FP25 -> 0 | FR29: Reacciones por cargas | FT29: =(FU25+FP29)*FT25 -> 0 | GH29: =(GG25+GL29)*GH25 -> 236.17418 | GJ29: Reacciones por cargas | GL29: =(GM25+GH28+GR28)*GL25 -> -58.23473 | GN29: =(GM25+GH28+GR28)*GN25 -> -58.23473 | GP29: Reacciones por cargas | GR29: =(GS25+GN29)*GR25 -> 0 | HD29: =(HC25+HH29)*HD25 -> 81.104428 | HF29: Reacciones por cargas | HH29: =(HI25+HD28+HN29)*HH25 -> 11.681859 | HJ29: =(HI25+HD28+HN29)*HJ25 -> 11.681859 | HL29: Reacciones por cargas | HN29: =(HO25+HJ28+HT29)*HN25 -> -129.24502 | HP29: =(HO25+HJ28+HT29)*HP25 -> -129.24502 | HR29: Reacciones por cargas | HT29: =(HU25+HP28+HZ28)*HT25 -> 503.10877 | HV29: =(HU25+HP28+HZ28)*HV25 -> 167.70292 | HX29: Reacciones por cargas | HZ29: =(IA25+HV29)*HZ25 -> 0 | IK29: vigaW | IL29: W 16x40 | IM29: 1195
B30: Ing. Arnoldo Coronado | M30: Densidad | P30: Angulo de Friccion | BU30: A | CH30: d= diametro | CJ30: To = periodo de la estructura | CM30: v = velocidad | EN30: Corniza | FJ30: =(FI25+FN30)*FJ25 -> -3375.0068 | FK30: =IF(FL24=0,0,IF(FK11=0,0,IF(FK12=0,0,FK12*(FL24-FK11)/FL24))) -> 0 | FL30: puntual 1 | FM30: =IF(FL24=0,0,IF(FK11=0,0,IF(FK12=0,0,FK12*FK11/FL24))) -> 0 | FN30: =(FO25+FJ29+FT29)*FN25 -> 0 | FP30: =(FO25+FJ29+FT29)*FP25 -> 0 | FQ30: =IF(FR24=0,0,IF(FQ11=0,0,IF(FQ12=0,0,FQ12*(FR24-FQ11)/FR24))) -> 0 | FR30: puntual 1 | FS30: =IF(FR24=0,0,IF(FQ11=0,0,IF(FQ12=0,0,FQ12*FQ11/FR24))) -> 0 | FT30: =(FU25+FP30)*FT25 -> 0 | GH30: =(GG25+GL30)*GH25 -> 236.57859 | GI30: =IF(GJ24=0,0,IF(GI11=0,0,IF(GI12=0,0,GI12*(GJ24-GI11)/GJ24))) -> 0 | GJ30: puntual 1 | GK30: =IF(GJ24=0,0,IF(GI11=0,0,IF(GI12=0,0,GI12*GI11/GJ24))) -> 0 | GL30: =(GM25+GH29+GR29)*GL25 -> -59.043546 | GN30: =(GM25+GH29+GR29)*GN25 -> -59.043546 | GO30: =IF(GP24=0,0,IF(GO11=0,0,IF(GO12=0,0,GO12*(GP24-GO11)/GP24))) -> 0 | GP30: puntual 1 | GQ30: =IF(GP24=0,0,IF(GO11=0,0,IF(GO12=0,0,GO12*GO11/GP24))) -> 0 | GR30: =(GS25+GN30)*GR25 -> 0 | HD30: =(HC25+HH30)*HD25 -> 81.331028 | HE30: =IF(HF24=0,0,IF(HE11=0,0,IF(HE12=0,0,HE12*(HF24-HE11)/HF24))) -> 250.78909 | HF30: puntual 1 | HG30: =IF(HF24=0,0,IF(HE11=0,0,IF(HE12=0,0,HE12*HE11/HF24))) -> 27.865455 | HH30: =(HI25+HD29+HN30)*HH25 -> 11.22866 | HJ30: =(HI25+HD29+HN30)*HJ25 -> 11.22866 | HK30: =IF(HL24=0,0,IF(HK11=0,0,IF(HK12=0,0,HK12*(HL24-HK11)/HL24))) -> 0 | HL30: puntual 1 | HM30: =IF(HL24=0,0,IF(HK11=0,0,IF(HK12=0,0,HK12*HK11/HL24))) -> 0 | HN30: =(HO25+HJ29+HT30)*HN25 -> -128.52696 | HP30: =(HO25+HJ29+HT30)*HP25 -> -128.52696 | HQ30: =IF(HR24=0,0,IF(HQ11=0,0,IF(HQ12=0,0,HQ12*(HR24-HQ11)/HR24))) -> 0 | HR30: puntual 1 | HS30: =IF(HR24=0,0,IF(HQ11=0,0,IF(HQ12=0,0,HQ12*HQ11/HR24))) -> 0 | HT30: =(HU25+HP29+HZ29)*HT25 -> 502.42597 | HV30: =(HU25+HP29+HZ29)*HV25 -> 167.47532 | HW30: =IF(HX24=0,0,IF(HW11=0,0,IF(HW12=0,0,HW12*(HX24-HW11)/HX24))) -> 0 | HX30: puntual 1 | HY30: =IF(HX24=0,0,IF(HW11=0,0,IF(HW12=0,0,HW12*HW11/HX24))) -> 0 | HZ30: =(IA25+HV30)*HZ25 -> 0 | IY30: Trabes T3
B31: Cedula: | L31: Peso 3: | M31: 2060 | N31: kg/m4 | O31: Ang 3 | P31: 30 | Q31: no cohesivo | BU31: 8.8 | BV31: m/s | BY31: La presion estatica se considerara como carga viva constante para las techumbres y canceleria | EF31: carga uniforme | FJ31: =(FI25+FN31)*FJ25 -> -3375.0068 | FK31: =IF(FL24=0,0,IF(FK13=0,0,IF(FK14=0,0,FK14*(FL24-FK13)/FL24))) -> 0 | FL31: puntual 2 | FM31: =IF(FL24=0,0,IF(FK13=0,0,IF(FK14=0,0,FK14*FK13/FL24))) -> 0 | FN31: =(FO25+FJ30+FT30)*FN25 -> 0 | FP31: =(FO25+FJ30+FT30)*FP25 -> 0 | FQ31: =IF(FR24=0,0,IF(FQ13=0,0,IF(FQ14=0,0,FQ14*(FR24-FQ13)/FR24))) -> 0 | FR31: puntual 2 | FS31: =IF(FR24=0,0,IF(FQ13=0,0,IF(FQ14=0,0,FQ14*FQ13/FR24))) -> 0 | FT31: =(FU25+FP31)*FT25 -> 0 | GH31: =(GG25+GL31)*GH25 -> 236.62914 | GI31: =IF(GJ24=0,0,IF(GI13=0,0,IF(GI14=0,0,GI14*(GJ24-GI13)/GJ24))) -> 0 | GJ31: puntual 2 | GK31: =IF(GJ24=0,0,IF(GI13=0,0,IF(GI14=0,0,GI14*GI13/GJ24))) -> 0 | GL31: =(GM25+GH30+GR30)*GL25 -> -59.144648 | GN31: =(GM25+GH30+GR30)*GN25 -> -59.144648 | GO31: =IF(GP24=0,0,IF(GO13=0,0,IF(GO14=0,0,GO14*(GP24-GO13)/GP24))) -> 0 | GP31: puntual 2 | GQ31: =IF(GP24=0,0,IF(GO13=0,0,IF(GO14=0,0,GO14*GO13/GP24))) -> 0 | GR31: =(GS25+GN31)*GR25 -> 0 | HD31: =(HC25+HH31)*HD25 -> 81.38193 | HE31: =IF(HF24=0,0,IF(HE13=0,0,IF(HE14=0,0,HE14*(HF24-HE13)/HF24))) -> 0 | HF31: puntual 2 | HG31: =IF(HF24=0,0,IF(HE13=0,0,IF(HE14=0,0,HE14*HE13/HF24))) -> 0 | HH31: =(HI25+HD30+HN31)*HH25 -> 11.126855 | HJ31: =(HI25+HD30+HN31)*HJ25 -> 11.126855 | HK31: =IF(HL24=0,0,IF(HK13=0,0,IF(HK14=0,0,HK14*(HL24-HK13)/HL24))) -> 0 | HL31: puntual 2 | HM31: =IF(HL24=0,0,IF(HK13=0,0,IF(HK14=0,0,HK14*HK13/HL24))) -> 0 | HN31: =(HO25+HJ30+HT31)*HN25 -> -128.34634 | HP31: =(HO25+HJ30+HT31)*HP25 -> -128.34634 | HQ31: =IF(HR24=0,0,IF(HQ13=0,0,IF(HQ14=0,0,HQ14*(HR24-HQ13)/HR24))) -> 0 | HR31: puntual 2 | HS31: =IF(HR24=0,0,IF(HQ13=0,0,IF(HQ14=0,0,HQ14*HQ13/HR24))) -> 0 | HT31: =(HU25+HP30+HZ30)*HT25 -> 502.1567 | HV31: =(HU25+HP30+HZ30)*HV25 -> 167.38557 | HW31: =IF(HX24=0,0,IF(HW13=0,0,IF(HW14=0,0,HW14*(HX24-HW13)/HX24))) -> 0 | HX31: puntual 2 | HY31: =IF(HX24=0,0,IF(HW13=0,0,IF(HW14=0,0,HW14*HW13/HX24))) -> 0 | HZ31: =(IA25+HV31)*HZ25 -> 0 | IK31: Conectores | IY31: =RM31 -> 0
B32: INGENIERO CIVIL.: 5533080 | L32: Cap Carga | M32: 11 | N32: ton/m2 | O32: con factores de seg | U32: 2007 | BU32: =BU31*3600/1000 -> 31.68 | BV32: km/hra | CH32: p= | CI32: =CN18 -> 933.28723 | CJ32: C= | CK32: 1.7 | CL32: d= | CM32: 0.5 | DV32: Fb= | DW32: 2310 | DX32: kg/cm^2 | DZ32: Fy = | EA32: 2130 | EB32: kg/cm^2 | EG32: claro en pulgadas | EH32: =EH16 -> 12 | EN32: Corniza de Cantera aproximadamente 0.06 m^2 osea 0.06 m^3 x cada metro lineal. Lo que equivale a unos 150 kg-metro lineal | FJ32: =(FI25+FN32)*FJ25 -> -3375.0068 | FK32: =IF(FL24=0,0,IF(FK15=0,0,IF(FK16=0,0,FK16*(FL24-FK15)/FL24))) -> 0 | FL32: puntual 3 | FM32: =IF(FL24=0,0,IF(FK15=0,0,IF(FK16=0,0,FK16*FK15/FL24))) -> 0 | FN32: =(FO25+FJ31+FT31)*FN25 -> 0 | FP32: =(FO25+FJ31+FT31)*FP25 -> 0 | FQ32: =IF(FR24=0,0,IF(FQ15=0,0,IF(FQ16=0,0,FQ16*(FR24-FQ15)/FR24))) -> 0 | FR32: puntual 3 | FS32: =IF(FR24=0,0,IF(FQ15=0,0,IF(FQ16=0,0,FQ16*FQ15/FR24))) -> 0 | FT32: =(FU25+FP32)*FT25 -> 0 | GH32: =(GG25+GL32)*GH25 -> 236.63546 | GI32: =IF(GJ24=0,0,IF(GI15=0,0,IF(GI16=0,0,GI16*(GJ24-GI15)/GJ24))) -> 0 | GJ32: puntual 3 | GK32: =IF(GJ24=0,0,IF(GI15=0,0,IF(GI16=0,0,GI16*GI15/GJ24))) -> 0 | GL32: =(GM25+GH31+GR31)*GL25 -> -59.157286 | GN32: =(GM25+GH31+GR31)*GN25 -> -59.157286 | GO32: =IF(GP24=0,0,IF(GO15=0,0,IF(GO16=0,0,GO16*(GP24-GO15)/GP24))) -> 0 | GP32: puntual 3 | GQ32: =IF(GP24=0,0,IF(GO15=0,0,IF(GO16=0,0,GO16*GO15/GP24))) -> 0 | GR32: =(GS25+GN32)*GR25 -> 0 | HD32: =(HC25+HH32)*HD25 -> 81.393591 | HE32: =IF(HF24=0,0,IF(HE15=0,0,IF(HE16=0,0,HE16*(HF24-HE15)/HF24))) -> 0 | HF32: puntual 3 | HG32: =IF(HF24=0,0,IF(HE15=0,0,IF(HE16=0,0,HE16*HE15/HF24))) -> 0 | HH32: =(HI25+HD31+HN32)*HH25 -> 11.103534 | HJ32: =(HI25+HD31+HN32)*HJ25 -> 11.103534 | HK32: =IF(HL24=0,0,IF(HK15=0,0,IF(HK16=0,0,HK16*(HL24-HK15)/HL24))) -> 0 | HL32: puntual 3 | HM32: =IF(HL24=0,0,IF(HK15=0,0,IF(HK16=0,0,HK16*HK15/HL24))) -> 0 | HN32: =(HO25+HJ31+HT32)*HN25 -> -128.30396 | HP32: =(HO25+HJ31+HT32)*HP25 -> -128.30396 | HQ32: =IF(HR24=0,0,IF(HQ15=0,0,IF(HQ16=0,0,HQ16*(HR24-HQ15)/HR24))) -> 0 | HR32: puntual 3 | HS32: =IF(HR24=0,0,IF(HQ15=0,0,IF(HQ16=0,0,HQ16*HQ15/HR24))) -> 0 | HT32: =(HU25+HP31+HZ31)*HT25 -> 502.08897 | HV32: =(HU25+HP31+HZ31)*HV25 -> 167.36299 | HW32: =IF(HX24=0,0,IF(HW15=0,0,IF(HW16=0,0,HW16*(HX24-HW15)/HX24))) -> 0 | HX32: puntual 3 | HY32: =IF(HX24=0,0,IF(HW15=0,0,IF(HW16=0,0,HW16*HW15/HX24))) -> 0 | HZ32: =(IA25+HV32)*HZ25 -> 0 | IK32: Reaccion M | IO32: Area Req | KC32: Block 2= Block liviano para divisiones. Este es de 10 cm de ancho y se empleara en el muro de la recamara que se encuentra sobre el voladizo así como en el muro en el eje h sobre trabe. Ambos en el Segundo nivel.
BU33: durante la epoca de vientos de santa ana tenemos rafagas en la region de hasta: | CH33: Ck= | CI33: 1 | CJ33: T= | CK33: =18*(CM32/CM33) -> 0.11572 | CL33: v= | CM33: =CF29 -> 77.773935 | DV33: Wu y = | DW33: =EH36 -> 120.97561 | DZ33: Wu x = | EA33: =DW33*0.25 -> 30.243902 | EG33: claro en pies= | EH33: =EH32/12 -> 1 | FJ33: =(FI25+FN33)*FJ25 -> -3375.0068 | FK33: =IF(FL24=0,0,IF(FK17=0,0,IF(FK18=0,0,FK18*(FL24-FK17)/FL24))) -> 0 | FL33: puntual 4 | FM33: =IF(FL24=0,0,IF(FK17=0,0,IF(FK18=0,0,FK18*FK17/FL24))) -> 0 | FN33: =(FO25+FJ32+FT32)*FN25 -> 0 | FP33: =(FO25+FJ32+FT32)*FP25 -> 0 | FQ33: =IF(FR24=0,0,IF(FQ17=0,0,IF(FQ18=0,0,FQ18*(FR24-FQ17)/FR24))) -> 0 | FR33: puntual 4 | FS33: =IF(FR24=0,0,IF(FQ17=0,0,IF(FQ18=0,0,FQ18*FQ17/FR24))) -> 0 | FT33: =(FU25+FP33)*FT25 -> 0 | GH33: =(GG25+GL33)*GH25 -> 236.63625 | GI33: =IF(GJ24=0,0,IF(GI17=0,0,IF(GI18=0,0,GI18*(GJ24-GI17)/GJ24))) -> 0 | GJ33: puntual 4 | GK33: =IF(GJ24=0,0,IF(GI17=0,0,IF(GI18=0,0,GI18*GI17/GJ24))) -> 0 | GL33: =(GM25+GH32+GR32)*GL25 -> -59.158865 | GN33: =(GM25+GH32+GR32)*GN25 -> -59.158865 | GO33: =IF(GP24=0,0,IF(GO17=0,0,IF(GO18=0,0,GO18*(GP24-GO17)/GP24))) -> 0 | GP33: puntual 4 | GQ33: =IF(GP24=0,0,IF(GO17=0,0,IF(GO18=0,0,GO18*GO17/GP24))) -> 0 | GR33: =(GS25+GN33)*GR25 -> 0 | HD33: =(HC25+HH33)*HD25 -> 81.396274 | HE33: =IF(HF24=0,0,IF(HE17=0,0,IF(HE18=0,0,HE18*(HF24-HE17)/HF24))) -> 0 | HF33: puntual 4 | HG33: =IF(HF24=0,0,IF(HE17=0,0,IF(HE18=0,0,HE18*HE17/HF24))) -> 0 | HH33: =(HI25+HD32+HN33)*HH25 -> 11.098168 | HJ33: =(HI25+HD32+HN33)*HJ25 -> 11.098168 | HK33: =IF(HL24=0,0,IF(HK17=0,0,IF(HK18=0,0,HK18*(HL24-HK17)/HL24))) -> 0 | HL33: puntual 4 | HM33: =IF(HL24=0,0,IF(HK17=0,0,IF(HK18=0,0,HK18*HK17/HL24))) -> 0 | HN33: =(HO25+HJ32+HT33)*HN25 -> -128.29415 | HP33: =(HO25+HJ32+HT33)*HP25 -> -128.29415 | HQ33: =IF(HR24=0,0,IF(HQ17=0,0,IF(HQ18=0,0,HQ18*(HR24-HQ17)/HR24))) -> 0 | HR33: puntual 4 | HS33: =IF(HR24=0,0,IF(HQ17=0,0,IF(HQ18=0,0,HQ18*HQ17/HR24))) -> 0 | HT33: =(HU25+HP32+HZ32)*HT25 -> 502.07307 | HV33: =(HU25+HP32+HZ32)*HV25 -> 167.35769 | HW33: =IF(HX24=0,0,IF(HW17=0,0,IF(HW18=0,0,HW18*(HX24-HW17)/HX24))) -> 0 | HX33: puntual 4 | HY33: =IF(HX24=0,0,IF(HW17=0,0,IF(HW18=0,0,HW18*HW17/HX24))) -> 0 | HZ33: =(IA25+HV33)*HZ25 -> 0 | IK33: =MAX(IM14:IM17) -> 10112.756 | IO33: =IK33/2500 -> 4.0451023
